<robot name="robot">

    <link name="base_footprint">
        <visual>
            <geometry>
                <sphere radius="0.001" />
            </geometry>
        </visual>
    </link>

    <link name="base_link">
        <visual>
            <geometry>
                <box size="0.6 0.2 0.1" />
            </geometry>
            <origin xyz="0 0 0" rpy="0 0 0" />
        </visual>
        <inertial>
            <origin xyz="0 0 0"/>
            <mass value="6" />
            <inertia ixx="1" ixy="0" ixz="0" iyy="1" iyz="0" izz="1" />
        </inertial>
        <collision>
            <geometry>
                <box size="0.6 0.2 0.1" />
            </geometry>
            <origin xyz="0 0 0" rpy="0 0 0" />
        </collision>
    </link>

    <gazebo reference="base_link">
        <material>Gazebo/Orange</material>
    </gazebo>

    <gazebo reference="left_front_wheel">
        <material>Gazebo/Black</material>
    </gazebo>

    <gazebo reference="right_front_wheel">
        <material>Gazebo/Black</material>
    </gazebo>

    <gazebo reference="left_back_wheel">
        <material>Gazebo/Black</material>
    </gazebo>

    <gazebo reference="right_back_wheel">
        <material>Gazebo/Black</material>
    </gazebo>

    <joint name="base_link2base_footprint" type="fixed">
        <parent link="base_footprint" />
        <child link="base_link"/>
        <origin xyz="0 0 0.2" />
    </joint>

    <link name="left_front_wheel">
        <visual>
            <geometry>
                <cylinder radius="0.08" length="0.06" />
            </geometry>
            <origin xyz="0 0 0" rpy="-1.5705 0 0" />
        </visual>
        <inertial>
            <origin xyz="0 0 0"/>
            <mass value="2" />
            <inertia ixx="1" ixy="0" ixz="0" iyy="1" iyz="0" izz="1" />
        </inertial>
        <collision>
            <geometry>
                <cylinder radius="0.08" length="0.06" />
            </geometry>
            <origin xyz="0 0 0" rpy="1.5705 0 0" />
        </collision>
    </link>

    <joint name="left_front_wheel_joint" type="continuous">
        <parent link="base_link"/>
        <child link="left_front_wheel" />
        <origin xyz="0.18 0.13 -0.05" rpy="0 0 0" />
        <axis xyz="0 1 0" />
    </joint>

    <link name="right_front_wheel">
        <visual>
            <geometry>
                <cylinder radius="0.08" length="0.06" />
            </geometry>
            <origin xyz="0 0 0" rpy="-1.5705 0 0" />
        </visual>
        <inertial>
            <origin xyz="0 0 0"/>
            <mass value="2" />
            <inertia ixx="1" ixy="0" ixz="0" iyy="1" iyz="0" izz="1" />
        </inertial>
        <collision>
            <geometry>
                <cylinder radius="0.1" length="0.06" />
            </geometry>
            <origin xyz="0 0 0" rpy="1.5705 0 0" />
        </collision>
    </link>

    <joint name="right_front_wheel_joint" type="continuous">
        <parent link="base_link"/>
        <child link="right_front_wheel" />
        <origin xyz="0.18 -0.13 -0.05" rpy="0 0 0" />
        <axis xyz="0 1 0" />
    </joint>


    <link name="left_back_wheel">
        <visual>
            <geometry>
                <cylinder radius="0.08" length="0.06" />
            </geometry>
            <origin xyz="0 0 0" rpy="-1.5705 0 0" />
        </visual>
        <inertial>
            <origin xyz="0 0 0"/>
            <mass value="2" />
            <inertia ixx="1" ixy="0" ixz="0" iyy="1" iyz="0" izz="1" />
        </inertial>
        <collision>
            <geometry>
                <cylinder radius="0.1" length="0.06" />
            </geometry>
            <origin xyz="0 0 0" rpy="1.5705 0 0" />
        </collision>
    </link>

    <joint name="left_back_wheel_joint" type="continuous">
        <parent link="base_link"/>
        <child link="left_back_wheel" />
        <origin xyz="-0.18 0.13 -0.05" rpy="0 0 0" />
        <axis xyz="0 1 0" />
    </joint>

    <link name="right_back_wheel">
        <visual>
            <geometry>
                <cylinder radius="0.08" length="0.06" />
            </geometry>
            <origin xyz="0 0 0" rpy="-1.5705 0 0" />
        </visual>
        <inertial>
            <origin xyz="0 0 0"/>
            <mass value="2" />
            <inertia ixx="1" ixy="0" ixz="0" iyy="1" iyz="0" izz="1" />
        </inertial>
        <collision>
            <geometry>
                <cylinder radius="0.1" length="0.06" />
            </geometry>
            <origin xyz="0 0 0" rpy="1.5705 0 0" />
        </collision>
    </link>

    <joint name="right_back_wheel_joint" type="continuous">
        <parent link="base_link"/>
        <child link="right_back_wheel" />
        <origin xyz="-0.18 -0.13 -0.05" rpy="0 0 0" />
        <axis xyz="0 1 0" />
    </joint>

</robot>
